<?xml version="1.0" ?>
<!-- =================================================================================== -->
<!-- |    This document was autogenerated by xacro from brazo_robert.xacro             | -->
<!-- |    EDITING THIS FILE BY HAND IS NOT RECOMMENDED                                 | -->
<!-- =================================================================================== -->
<robot name="brazo_robert">
  <!-- Base del brazo -->
  <link name="base_link">
    <inertial>
      <mass value="1.0"/>
      <origin xyz="0 0 0.15"/>
      <inertia ixx="0.01" ixy="0" ixz="0" iyy="0.01" iyz="0" izz="0.01"/>
    </inertial>
    <collision>
      <origin xyz="0 0 0.15"/>
      <geometry>
        <cylinder length="0.3" radius="0.5"/>
      </geometry>
    </collision>
    <visual>
      <origin xyz="0 0 0.15"/>
      <geometry>
        <cylinder length="0.3" radius="0.5"/>
      </geometry>
      <material name="blue">
        <color rgba="0 0 0.8 1"/>
      </material>
    </visual>
  </link>
  <link name="segmento1_link">
    <inertial>
      <mass value="1.0"/>
      <origin xyz="0 0 0.1"/>
      <inertia ixx="0.01" ixy="0" ixz="0" iyy="0.01" iyz="0" izz="0.01"/>
    </inertial>
    <collision>
      <origin xyz="0 0 0.1"/>
      <!-- 🔹 Mueve el cubo hacia arriba -->
      <geometry>
        <box size="0.1 0.1 0.2"/>
      </geometry>
    </collision>
    <visual>
      <origin xyz="0 0 0.1"/>
      <!-- 🔹 Mueve el cubo hacia arriba -->
      <geometry>
        <box size="0.1 0.1 0.2"/>
      </geometry>
      <material name="0.8 0 0 1">
        <color rgba="0.8 0 0 1"/>
      </material>
    </visual>
  </link>
  <joint name="segmento1_joint" type="revolute">
    <parent link="base_link"/>
    <child link="segmento1_link"/>
    <origin rpy="0 0 0" xyz="0 0 0.3"/>
    <axis xyz="0 0 1"/>
    <limit effort="100.0" lower="-1.57" upper="1.57" velocity="0.5"/>
  </joint>
  <link name="segmento2_link">
    <inertial>
      <mass value="1.0"/>
      <origin xyz="0 0 0.35"/>
      <inertia ixx="0.01" ixy="0" ixz="0" iyy="0.01" iyz="0" izz="0.01"/>
    </inertial>
    <collision>
      <origin xyz="0 0 0.35"/>
      <!-- 🔹 Mueve el cubo hacia arriba -->
      <geometry>
        <box size="0.1 0.1 0.7"/>
      </geometry>
    </collision>
    <visual>
      <origin xyz="0 0 0.35"/>
      <!-- 🔹 Mueve el cubo hacia arriba -->
      <geometry>
        <box size="0.1 0.1 0.7"/>
      </geometry>
      <material name="0 0.8 0 1">
        <color rgba="0 0.8 0 1"/>
      </material>
    </visual>
  </link>
  <joint name="segmento2_joint" type="revolute">
    <parent link="segmento1_link"/>
    <child link="segmento2_link"/>
    <origin rpy="0 0 0" xyz="0 0 0.2"/>
    <axis xyz="0 1 0"/>
    <limit effort="100.0" lower="-1.57" upper="1.57" velocity="0.5"/>
  </joint>
  <link name="segmento3_link">
    <inertial>
      <mass value="1.0"/>
      <origin xyz="0 0 0.1"/>
      <inertia ixx="0.01" ixy="0" ixz="0" iyy="0.01" iyz="0" izz="0.01"/>
    </inertial>
    <collision>
      <origin xyz="0 0 0.1"/>
      <!-- 🔹 Mueve el cubo hacia arriba -->
      <geometry>
        <box size="0.1 0.1 0.2"/>
      </geometry>
    </collision>
    <visual>
      <origin xyz="0 0 0.1"/>
      <!-- 🔹 Mueve el cubo hacia arriba -->
      <geometry>
        <box size="0.1 0.1 0.2"/>
      </geometry>
      <material name="0 0.8 0 1">
        <color rgba="0 0.8 0 1"/>
      </material>
    </visual>
  </link>
  <joint name="segmento3_joint" type="revolute">
    <parent link="segmento2_link"/>
    <child link="segmento3_link"/>
    <origin rpy="0 0 0" xyz="0 0 0.7"/>
    <axis xyz="0 1 0"/>
    <limit effort="100.0" lower="-1.57" upper="1.57" velocity="0.5"/>
  </joint>
  <link name="segmento4_link">
    <inertial>
      <mass value="0.5"/>
      <origin xyz="0 0 0.2"/>
      <inertia ixx="0.01" ixy="0" ixz="0" iyy="0.01" iyz="0" izz="0.01"/>
    </inertial>
    <collision>
      <origin xyz="0 0 0.2"/>
      <geometry>
        <cylinder length="0.4" radius="0.05"/>
      </geometry>
    </collision>
    <visual>
      <origin xyz="0 0 0.2"/>
      <geometry>
        <cylinder length="0.4" radius="0.05"/>
      </geometry>
      <material name="0.8 0.8 0 1">
        <color rgba="0.8 0.8 0 1"/>
      </material>
    </visual>
  </link>
  <joint name="segmento4_rot" type="continuous">
    <!-- 🔹 Tipo continuo para rotación infinita -->
    <parent link="segmento3_link"/>
    <child link="segmento4_link"/>
    <origin rpy="0 0 0" xyz="0 0 0.2"/>
    <axis xyz="0 0 1"/>
  </joint>
  <link name="segmento5_link">
    <inertial>
      <mass value="1.0"/>
      <origin xyz="0 0 0.1"/>
      <inertia ixx="0.01" ixy="0" ixz="0" iyy="0.01" iyz="0" izz="0.01"/>
    </inertial>
    <collision>
      <origin xyz="0 0 0.1"/>
      <!-- 🔹 Mueve el cubo hacia arriba -->
      <geometry>
        <box size="0.1 0.1 0.2"/>
      </geometry>
    </collision>
    <visual>
      <origin xyz="0 0 0.1"/>
      <!-- 🔹 Mueve el cubo hacia arriba -->
      <geometry>
        <box size="0.1 0.1 0.2"/>
      </geometry>
      <material name="0 0.8 0 1">
        <color rgba="0 0.8 0 1"/>
      </material>
    </visual>
  </link>
  <joint name="segmento5_joint" type="revolute">
    <parent link="segmento4_link"/>
    <child link="segmento5_link"/>
    <origin rpy="0 0 0" xyz="0 0 0.4"/>
    <axis xyz="0 1 0"/>
    <limit effort="100.0" lower="-1.57" upper="1.57" velocity="0.5"/>
  </joint>
  <!-- Gripper izquierdo -->
  <joint name="gripper_left_joint" type="prismatic">
    <parent link="segmento5_link"/>
    <child link="gripper_left"/>
    <origin xyz="0 0.05 0.2"/>
    <axis xyz="0 1 0"/>
    <limit effort="10.0" lower="0.0" upper="0.05" velocity="0.1"/>
  </joint>
  <link name="gripper_left">
    <inertial>
      <mass value="0.1"/>
      <origin xyz="0 0 0"/>
      <inertia ixx="0.001" ixy="0" ixz="0" iyy="0.001" iyz="0" izz="0.001"/>
    </inertial>
    <visual>
      <geometry>
        <cylinder length="0.2" radius="0.05"/>
      </geometry>
      <material name="black">
        <color rgba="0.2 0.2 0.2 1"/>
      </material>
    </visual>
  </link>
  <!-- Gripper derecho -->
  <joint name="gripper_right_joint" type="prismatic">
    <parent link="segmento5_link"/>
    <child link="gripper_right"/>
    <origin xyz="0 -0.05 0.2"/>
    <axis xyz="0 -1 0"/>
    <!-- Se mueve en dirección opuesta -->
    <limit effort="10.0" lower="0.0" upper="0.05" velocity="0.1"/>
  </joint>
  <link name="gripper_right">
    <inertial>
      <mass value="0.1"/>
      <origin xyz="0 0 0"/>
      <inertia ixx="0.001" ixy="0" ixz="0" iyy="0.001" iyz="0" izz="0.001"/>
    </inertial>
    <visual>
      <geometry>
        <cylinder length="0.2" radius="0.05"/>
      </geometry>
      <material name="black">
        <color rgba="0.2 0.2 0.2 1"/>
      </material>
    </visual>
  </link>
</robot>
